<sdf version='1.8'>
  <model name='chimera_URDF_real'>
    <link name='base_link'>
      <velocity_decay>
        <linear>1000</linear>
        <angular>1000</angular>
      </velocity_decay>
      <pose degrees="true">0 0 0 180 0 0</pose>
      <inertial>
        <pose>0 0 0 0 0 0</pose>
        <mass>5.16</mass> <!-- 5.56 - 4x0.1 from thruster links-->
        <inertia>
          <ixx>0.03</ixx>
          <ixy>0</ixy>
          <ixz>0</ixz>
          <iyy>0.04</iyy>
          <iyz>0</iyz>
          <izz>0.04</izz>
        </inertia>
      </inertial>
      <!-- <collision name='base_link_collision'>
        <pose>0 0 0 0 0 0</pose>
        <geometry>
          <mesh>
            <scale>1 1 1</scale>
            <uri>./meshes/base_link.STL</uri>
          </mesh>
        </geometry>
      </collision> -->
      <collision name="main_body_buoyancy">
        <pose>-1.56312874363132e-05 -1.76467617646643e-06 0.161160143310051 0 0 0</pose>
        <geometry>
          <sphere>
            <radius>0.1098994184</radius>
          </sphere>
        </geometry>
      </collision>
      <visual name='base_link_visual'>
        <pose>0 0 0 0 0 0</pose>
        <geometry>
          <mesh>
            <scale>1 1 1</scale>
            <uri>./meshes/base_link.STL</uri>
          </mesh>
        </geometry>
        <material>
          <diffuse>0.622549 0.622549 0.622549 1</diffuse>
          <ambient>0.622549 0.622549 0.622549 1</ambient>
        </material>
      </visual>
    </link>

    <link name='thruster_front_left'>
      <pose>0.225552 -0.244729 -0.1395 0 0 0.523599</pose>
      <inertial>
        <mass>0.1</mass>
      </inertial>
      <visual name="visual">
        <pose>0.1 0 0 0 0 0</pose>
        <geometry>
          <ellipsoid>
            <radii>0.1 0.01 0.01</radii>
          </ellipsoid>
        </geometry>
        <material>
          <ambient>1.0 0.0 0 0.9</ambient>
          <diffuse>1.0 0.0 0 0.9</diffuse>
          <specular>1.0 0.0 0.9</specular>
        </material>
      </visual>
      <visual name="prop">
        <geometry>
          <box>
            <size>0.005 0.076 0.02</size>
          </box>
        </geometry>
        <material>
          <ambient>1.0 0.0 0 1</ambient>
          <diffuse>1.0 0.0 0 1</diffuse>
          <specular>1.0 0.0 1</specular>
        </material>
      </visual>
    </link>
    <link name='thruster_front_right'>
      <pose>0.225552 0.244729 -0.1395 0 0 -0.523599</pose>
      <inertial>
        <mass>0.1</mass>
      </inertial>
      <visual name="visual">
        <pose>0.1 0 0 0 0 0</pose>
        <geometry>
          <ellipsoid>
            <radii>0.1 0.01 0.01</radii>
          </ellipsoid>
        </geometry>
        <material>
          <ambient>0.0 1.0 0 0.9</ambient>
          <diffuse>0.0 1.0 0 0.9</diffuse>
          <specular>0.0 1.0 0 0.9</specular>
        </material>
      </visual>
      <visual name="prop">
        <geometry>
          <box>
            <size>0.005 0.076 0.02</size>
          </box>
        </geometry>
        <material>
          <ambient>0.0 1.0 0 1</ambient>
          <diffuse>0.0 1.0 0 1</diffuse>
          <specular>0.0 1.0 0 1</specular>
        </material>
      </visual>
    </link>
    <link name='thruster_back_left'>
      <pose>-0.225552 -0.244729 -0.1395 0 0 -0.523599</pose>
      <inertial>
        <mass>0.1</mass>
      </inertial>
      <visual name="visual">
        <pose>0.1 0 0 0 0 0</pose>
        <geometry>
          <ellipsoid>
            <radii>0.1 0.01 0.01</radii>
          </ellipsoid>
        </geometry>
        <material>
          <ambient>1.0 0.5 0.5 0.9</ambient>
          <diffuse>1.0 0.5 0.5 0.9</diffuse>
          <specular>1.0 0.5 0.5 0.9</specular>
        </material>
      </visual>
      <visual name="prop">
        <geometry>
          <box>
            <size>0.005 0.076 0.02</size>
          </box>
        </geometry>
        <material>
          <ambient>1.0 0.5 0.5 1</ambient>
          <diffuse>1.0 0.5 0.5 1</diffuse>
          <specular>1.0 0.5 0.5 1</specular>
        </material>
      </visual>
    </link>
    <link name='thruster_back_right'>
      <pose>-0.225552 0.244729 -0.1395 0 0 0.523599</pose>
      <inertial>
        <mass>0.1</mass>
      </inertial>
      <visual name="visual">
        <pose>0.1 0 0 0 0 0</pose>
        <geometry>
          <ellipsoid>
            <radii>0.1 0.01 0.01</radii>
          </ellipsoid>
        </geometry>
        <material>
          <ambient>0.5 1.0 0.5 0.9</ambient>
          <diffuse>0.5 1.0 0.5 0.9</diffuse>
          <specular>0.5 1.0 0.5 0.9</specular>
        </material>
      </visual>
      <visual name="prop">
        <geometry>
          <box>
            <size>0.005 0.076 0.02</size>
          </box>
        </geometry>
        <material>
          <ambient>0.5 1.0 0.5 1</ambient>
          <diffuse>0.5 1.0 0.5 1</diffuse>
          <specular>0.5 1.0 0.5 1</specular>
        </material>
      </visual>
    </link>

    <joint name="thruster_joint_FL" type="revolute">
      <pose>0 0 0 0 0 0</pose>
      <parent>base_link</parent>
      <child>thruster_front_left</child>
      <axis>
        <xyz>1 0 0</xyz>
        <limit></limit>
      </axis>
    </joint>

    <joint name="thruster_joint_FR" type="revolute">
      <pose>0 0 0 0 0 0</pose>
      <parent>base_link</parent>
      <child>thruster_front_right</child>
      <axis>
        <xyz>1 0 0</xyz>
        <limit></limit>
      </axis>
    </joint>

    <joint name="thruster_joint_BL" type="revolute">
      <pose>0 0 0 0 0 0</pose>
      <parent>base_link</parent>
      <child>thruster_back_left</child>
      <axis>
        <xyz>1 0 0</xyz>
        <limit></limit>
      </axis>
    </joint>

    <joint name="thruster_joint_BR" type="revolute">
      <pose>0 0 0 0 0 0</pose>
      <parent>base_link</parent>
      <child>thruster_back_right</child>
      <axis>
        <xyz>1 0 0</xyz>
        <limit></limit>
      </axis>
    </joint>

  </model>
</sdf>
